Workbook
Name AIRE: INTERFAZ!$D$29
Name ETC: INTERFAZ!$D$29:$D$33
Name PLANO1: INTERFAZ!$D$29:$D$33
Name PLANO2: INTERFAZ!$D$29:$D$33
Name WESSUN: INTERFAZ!$D$29:$D$33

Sheet INTERFAZ
J3: GUIA SOLAR TÉRMICA EN INDUSTRIA
J4: Simulador de viabilidad. (Versión julio 2022)
B7: DATOS GENERALES
B9: Nombre del proyecto | E9: Ejemplo
B11: Empresa
B13: Autor de la simulación
B15: Teléfono | F15: email
B19: PARÁMETROS TÉCNICOS
B21: Demanda proceso industrial [MWh/año] | E21: 5000
B22: Seleccione Localidad | E22: Madrid | H22: Aportación solar [kWh/m2.año] | I22: =ROUND(B40*E25^2+C40*E25+D40,1) -> 450.6
B23: Seleccione Captador Solar | E23: Captador TUBO DE VACIO-CPC
B24: Seleccione Proceso | E24: Carnica | H24: Área de captación solar [m2] | I24: =ROUND(B94*E25^2+C94*E25+D94,1)*E21/5000 -> 5894.3
B25: Sel. Cobertura Solar Objetivo | E25: 0.45
B26: Fuente de energía convencional | E26: GLP | H26: Potencia nominal solar [kW] | I26: =I24*0.7 -> 4126.01
B27: Eficiencia del sistema de generación de energía convencional [%] | E27: 90
A29: =C29 -> - | B29: AIRE | C29: =IF(E24="Secado","Captador de AIRE","-") -> - | D29: Secado | E29: Barcelona | F29: 0.3
A30: =C30 -> Captador TUBO DE VACIO-CPC | B30: TUBO DE VACIO | C30: Captador TUBO DE VACIO-CPC | D30: Carnica | E30: Bilbao | F30: 0.45
A31: =C31 -> Captador PLANO Estándard | B31: PLANO1 | C31: Captador PLANO Estándard | D31: Bebidas | E31: Madrid | F31: 0.6
A32: =C32 -> Captador PLANO Gran Formato | B32: PLANO2 | C32: Captador PLANO Gran Formato | D32: Lacteos | E32: Sevilla | F32: 0.75
A33: =C33 -> Concentrador con TUBO DE VACIO-CPC | B33: WESSUN | C33: Concentrador con TUBO DE VACIO-CPC | D33: Farmaceutica | E33: Valencia
B35: Locación | C35: =E22 -> Madrid | E35: ID
B36: Proceso | C36: =E24 -> Carnica | E36: =_xlfn.CONCAT($C$35,$C$36,$C$37,0.3) -> MadridCarnicaPLANO20,3 | H36: Resultados Simulaciones
B37: Captador | C37: =VLOOKUP(E23,A29:B33,2) -> PLANO2 | D37: =VLOOKUP(C37,B29:C33,2) -> Captador PLANO Gran Formato | E37: =_xlfn.CONCAT($C$35,$C$36,$C$37,0.45) -> MadridCarnicaPLANO20,45 | H37: FS Real | I37: Aportación Solar [kWh/m2.año] | J37: =LISTADO!K2 -> Área Solar [m2]
E38: =_xlfn.CONCAT($C$35,$C$36,$C$37,0.6) -> MadridCarnicaPLANO20,6 | H38: [%]
B39: Ajuste Polinomio de grado 2 | E39: =_xlfn.CONCAT($C$35,$C$36,$C$37,0.75) -> MadridCarnicaPLANO20,75 | H39: =VLOOKUP(E36,LISTADO!$B$2:$O$522,12,FALSE) -> 0.27144248 | I39: =VLOOKUP(E36,LISTADO!$B$2:$O$522,11,FALSE) -> 510.49398 | J39: =VLOOKUP(E36,LISTADO!$B$2:$O$522,10,FALSE) -> 3076.8599
B40: {=LINEST(I39:I42,H39:H42^{1,2},,1)} -> -437.02164 | C40: -21.07519 | D40: 548.5942 | H40: =VLOOKUP(E37,LISTADO!$B$2:$O$522,12,FALSE) -> 0.3941187 | I40: =VLOOKUP(E37,LISTADO!$B$2:$O$522,11,FALSE) -> 473.08136 | J40: =VLOOKUP(E37,LISTADO!$B$2:$O$522,10,FALSE) -> 4863.2522
B41: 64.658792 | C41: 54.172197 | D41: 10.699293 | H41: =VLOOKUP(E38,LISTADO!$B$2:$O$522,12,FALSE) -> 0.49630501 | I41: =VLOOKUP(E38,LISTADO!$B$2:$O$522,11,FALSE) -> 429.58153 | J41: =VLOOKUP(E38,LISTADO!$B$2:$O$522,10,FALSE) -> 6856.7209
B42: 0.99980035 | C42: 1.21585 | D42: #N/A | H42: =VLOOKUP(E39,LISTADO!$B$2:$O$522,12,FALSE) -> 0.56635165 | I42: =VLOOKUP(E39,LISTADO!$B$2:$O$522,11,FALSE) -> 396.89173 | J42: =VLOOKUP(E39,LISTADO!$B$2:$O$522,10,FALSE) -> 8601.2094
B43: 2503.8878 | C43: 1 | D43: #N/A
B44: 7402.9507 | C44: 1.4782912 | D44: #N/A
B46: PARÁMETROS FINANCIEROS Y DE INVERSIÓN
B49: Coste estimado por m2 apertura | E49: 450 | F49: €/m2
B51: Coste de energía convencional bruto | E51: 33.19 | F51: €/MWh PCI
B53: Coste de energía convencional (neto) | E53: =E51/E27*100 -> 36.877778 | F53: €/MWh útil
B55: Coeficiente de emisiones de CO2 (asignado a la fuente de energía convencional) | E55: =IF(E26=B501,D501,IF(E26=B502,D502,IF(E26=B503,D503,IF(E26=B504,D504,IF(E26=B505,D505,IF(E26=B506,D506,"Error")))))) -> 0.22716 | F55: ton CO2/MWh
B57: Precio de CO2 evitado | E57: 20 | F57: €/ton CO2 evitado
B59: Coste estimado de operación y mantenimiento | E59: 2 | F59: % anual
B61: Incremento anual del coste de la Energía estimado | E61: 2 | F61: % anual
B63: Inflación general. % Anual estimado | E63: 1 | F63: % anual
B65: Vida útil estimada de la instalación (Valor máximo 30 años) | E65: 30 | F65: Años
...

Sheet AYUDA
J3: GUIA SOLAR TÉRMICA EN INDUSTRIA
J4: Simulador de viabilidad. (Versión julio 2022)
B8: OBJETO DEL SIMULADOR
B10: Este simulador ha sido desarrollado como complemento a la Guía Solar Térmica en Industria. Su propósito es permitir al usuario realizar un pre-dimensionado sencillo y determinar la contribución solar al proceso industrial como primera aproximación. Facilita, a través de la modificación de diferentes variables, simular la viabilidad de la instalación, mediante el cálculo estimado de la rentabilidad de la instalación (TIR) y del coste nivelado de generación de la energía. Esta herramienta parte de la caracterización de perfiles de consumo estándar que han sido definidos para la simulación de instalaciones de 5 procesos industriales diferentes: secado, industria cárnica, bebidas, lácteos e industrias farmacéuticas. Las instalaciones pueden simularse en 5 ubicaciones geográficas diferentes que pueden ser consideradas representativas por sus niveles de radiación solar de las diferentes zonas señaladas en los mapas de radiación solar en España. Finalmente, la herramienta desarrollada permite al usuario considerar en sus cálculos la utilización de 5 tecnologías diferentes de captadores solares.
B16: REQUISITOS
B17: Este simulador ha sido desarrollado con Microsoft 365 Excell version 2207 Si dispone de versiones anteriores se recomienda que actualice su cuenta de Microsoft para asegurar un correcto funcionamiento.
B19: HIPÓTESIS Y EXCLUSIONES
B21: ELEMENTOS INCLUIDOS EN LA SIMULACIÓN
B23: Para la realización de las simulaciones han sido considerados: - Campo de captadores - Tuberías circuito primario - Intercambiador primario‐secundario - Acumulación solar (acumulador vertical de agua) - Demanda de proceso caracterizada por una potencia y dos temperaturas de proceso*1 que entra en la parte inferior de la acumulación solar. - Control del sistema por sensor crepuscular, delta T secundario y Tmax acumulación
B25: ELEMENTOS EXCLUIDOS EN LA SIMULACIÓN
B27: Para la realización de las simulacioneshan sido excluidos los siguientes elementos: - Sombras horizonte y sombres entre filas captadoes - Consumos parasitarios (parametrización correcta) - Equipos Auxiliares, Boilers, Bombas de calor, etc - Intercambiador de proceso ‐> *1 se puede integrar mediante un delta T en la temperatura de retorno e impulsión de proceso
B29: LOCALIZACIONES CLIMÁTICAS
B31: Se han tenido en consideración 5 localizaciones climáticas cuyas características se consideran representativas. El usuario asignará a la localización de la instalación que desee simular la zona climática correspondiente en función del mapa adjunto. A. Sevilla B. Valencia C. Barcelona D. Madrid E. Bilbao
B33: PROCESOS INDUSTRIALES
... B43: Para cada una de los tipos de empresa se han definido unos perfiles base de consumos en los que se han considerado los principales parámetros de funcionamiento de los procesos. A continuación se indican los valores de referencia que se han considerado: Demanda anual de energía 5GWh.
D44: Secado | E44: Cárnica | F44: Lácteos | G44: Bebidas | H44: Farmacéutica
B45: MAX (kWh) | D45: 1368.36 | E45: 1360.63 | F45: 789.86 | G45: 1302.87 | H45: 1237.17
B46: TOTAL (kWh/año) | D46: 5000000 | E46: 5000000 | F46: 5000000 | G46: 5000000 | H46: 5000000
B47: T Impulsión (ºC) | D47: 60 | E47: 120 | F47: 120 | G47: 60 | H47: 120
B48: T Retorno (ºC) | D48: 15 | E48: 60 | F48: 60 | G48: 15 | H48: 60
B49: Horas de operación (hrs) | D49: 3654 | E49: 4437 | F49: 7564 | G49: 6316 | H49: 4437
B51: CAPTADORES SOLARES
B53: Para la simulación se consideran captadores solares con las siguientes características
C55: C | D55: ao | E55: a1 | F55: a2 | G55: IAM
B56: UFPC-Air* | D56: 0.94 | E56: 9.6 | F56: 0 | G56: El del plano 0,999
B57: FPC1 | D57: 0.818 | E57: 3.748 | F57: 0.0016 | G57: El del plano 0,88
B58: FPC2 | D58: 0.857 | E58: 3.083 | F58: 0.013 | G58: El del plano 0,91
B59: ETC | D59: 0.642 | E59: 0.89 | F59: 0.001 | G59: Linuo
B60: WeSSun | C60: 1.43 | D60: 0.6098 | E60: 0.3538 | F60: 0.0055 | G60: IAM_LIN_WeSSun_1R_Giro
B62: * Captador de aire se ha considerado únicamente para el proceso de secado con volumen de acumulación menor
B64: FRACCIONES SOLARES
B66: El usuario puede realizar simulaciones con niveles de objetivo de cobertura solar: - 30% - 45% - 60% - 75%
B68: CRITERIOS DE DIMENSIONADO PARA EL CÁLCULO DE LAS SIMULACIONES
B70: La herramienta ha sido diseñada teniendo en cuenta los siguientes criterios: - Área campo de captadores: dimensionado según la Gth y las Eta para el punto de trabajo del captador según las temperaturas de proceso - Azimut: 0° - Slope: Latitud – 5°? (si es el aire Fachada) - Caudal de campo ‐ Salto térmico campo de captadores: min (20º y Salto de proceso/Demanda) - Tuberías y equipos de recirculación en base al caudal de campo según correlaciones habituales - DTLM HX primario 7ºC para todos - Volumen acumulación: 75 l/m2 para procesos continuos – 125 l/m2 para procesos interrumpidos durante fin de semana. - Control solar crepuscular y deltaT secundario y temperatura máxima acumulador (100ºC o según proceso?) - Para el captador de aire aplicado a un proceso de secado considera un sistema sin intercambiadores y sin almacenamiento, consigna del aire 65º, 24/7 todo el año pero variable

Sheet LISTADO
A2: SIM | B2: ID | C2: ID2 | D2: Locación | E2: Proceso | F2: FS fija | G2: T° Impulsión [°C] | H2: T° Retorno [°C] | I2: Captador2 | J2: Captador | K2: Área Solar [m2] | L2: Producción Solar Captador [kWh/m2.año] | M2: FS | N2: Producción Específica [kWh/m2.año] | O2: TPM
A3: 1 | B3: =_xlfn.CONCAT(D3,E3,J3,F3) -> BarcelonaBebidasAIRE0,3 | C3: =_xlfn.CONCAT(D3,E3,I3,F3) -> BarcelonaBebidasAire0,3 | D3: Barcelona | E3: Bebidas | F3: 0.3 | G3: =IF(OR($E3="Secado",$E3="Bebidas"),60,120) -> 60 | H3: =IF(OR($E3="Secado",$E3="Bebidas"),15,60) -> 15 | I3: =IF(J3="AIRE","Aire",IF(J3="ETC","ETC",IF(J3="PLANO1","FPC1",IF(J3="PLANO2","FPC2",IF(J3="WESSUN","WeSSun"))))) -> Aire | J3: AIRE | K3: 2231.2121 | L3: 750.80166 | M3: 0.32870787 | N3: 736.59047
A4: 2 | B4: =_xlfn.CONCAT(D4,E4,J4,F4) -> BarcelonaBebidasAIRE0,45 | C4: =_xlfn.CONCAT(D4,E4,I4,F4) -> BarcelonaBebidasAire0,45 | D4: Barcelona | E4: Bebidas | F4: 0.45 | G4: =IF(OR($E4="Secado",$E4="Bebidas"),60,120) -> 60 | H4: =IF(OR($E4="Secado",$E4="Bebidas"),15,60) -> 15 | I4: =IF(J4="AIRE","Aire",IF(J4="ETC","ETC",IF(J4="PLANO1","FPC1",IF(J4="PLANO2","FPC2",IF(J4="WESSUN","WeSSun"))))) -> Aire | J4: AIRE | K4: 3592.3514 | L4: 703.83478 | M4: 0.4923489 | N4: 685.25311
A5: 3 | B5: =_xlfn.CONCAT(D5,E5,J5,F5) -> BarcelonaBebidasAIRE0,6 | C5: =_xlfn.CONCAT(D5,E5,I5,F5) -> BarcelonaBebidasAire0,6 | D5: Barcelona | E5: Bebidas | F5: 0.6 | G5: =IF(OR($E5="Secado",$E5="Bebidas"),60,120) -> 60 | H5: =IF(OR($E5="Secado",$E5="Bebidas"),15,60) -> 15 | I5: =IF(J5="AIRE","Aire",IF(J5="ETC","ETC",IF(J5="PLANO1","FPC1",IF(J5="PLANO2","FPC2",IF(J5="WESSUN","WeSSun"))))) -> Aire | J5: AIRE | K5: 5169.0174 | L5: 634.02289 | M5: 0.63171851 | N5: 611.04396
A6: 4 | B6: =_xlfn.CONCAT(D6,E6,J6,F6) -> BarcelonaBebidasAIRE0,75 | C6: =_xlfn.CONCAT(D6,E6,I6,F6) -> BarcelonaBebidasAire0,75 | D6: Barcelona | E6: Bebidas | F6: 0.75 | G6: =IF(OR($E6="Secado",$E6="Bebidas"),60,120) -> 60 | H6: =IF(OR($E6="Secado",$E6="Bebidas"),15,60) -> 15 | I6: =IF(J6="AIRE","Aire",IF(J6="ETC","ETC",IF(J6="PLANO1","FPC1",IF(J6="PLANO2","FPC2",IF(J6="WESSUN","WeSSun"))))) -> Aire | J6: AIRE | K6: 7016.8022 | L6: 557.57332 | M6: 0.7447144 | N6: 530.64903
A7: 5 | B7: =_xlfn.CONCAT(D7,E7,J7,F7) -> BarcelonaCarnicaAIRE0,3 | C7: =_xlfn.CONCAT(D7,E7,I7,F7) -> BarcelonaCarnicaAire0,3 | D7: Barcelona | E7: Carnica | F7: 0.3 | G7: =IF(OR($E7="Secado",$E7="Bebidas"),60,120) -> 120 | H7: =IF(OR($E7="Secado",$E7="Bebidas"),15,60) -> 60 | I7: =IF(J7="AIRE","Aire",IF(J7="ETC","ETC",IF(J7="PLANO1","FPC1",IF(J7="PLANO2","FPC2",IF(J7="WESSUN","WeSSun"))))) -> Aire | J7: AIRE | K7: 3456.4713 | L7: 33.654977 | M7: 0.0094163706 | N7: 13.620882
A8: 6 | B8: =_xlfn.CONCAT(D8,E8,J8,F8) -> BarcelonaCarnicaAIRE0,45 | C8: =_xlfn.CONCAT(D8,E8,I8,F8) -> BarcelonaCarnicaAire0,45 | D8: Barcelona | E8: Carnica | F8: 0.45 | G8: =IF(OR($E8="Secado",$E8="Bebidas"),60,120) -> 120 | H8: =IF(OR($E8="Secado",$E8="Bebidas"),15,60) -> 60 | I8: =IF(J8="AIRE","Aire",IF(J8="ETC","ETC",IF(J8="PLANO1","FPC1",IF(J8="PLANO2","FPC2",IF(J8="WESSUN","WeSSun"))))) -> Aire | J8: AIRE | K8: 5184.7069 | L8: 36.423312 | M8: 0.017176324 | N8: 16.563826
A9: 7 | B9: =_xlfn.CONCAT(D9,E9,J9,F9) -> BarcelonaCarnicaAIRE0,6 | C9: =_xlfn.CONCAT(D9,E9,I9,F9) -> BarcelonaCarnicaAire0,6 | D9: Barcelona | E9: Carnica | F9: 0.6 | G9: =IF(OR($E9="Secado",$E9="Bebidas"),60,120) -> 120 | H9: =IF(OR($E9="Secado",$E9="Bebidas"),15,60) -> 60 | I9: =IF(J9="AIRE","Aire",IF(J9="ETC","ETC",IF(J9="PLANO1","FPC1",IF(J9="PLANO2","FPC2",IF(J9="WESSUN","WeSSun"))))) -> Aire | J9: AIRE | K9: 6912.9425 | L9: 38.965391 | M9: 0.02669574 | N9: 19.307839
A10: 8 | B10: =_xlfn.CONCAT(D10,E10,J10,F10) -> BarcelonaCarnicaAIRE0,75 | C10: =_xlfn.CONCAT(D10,E10,I10,F10) -> BarcelonaCarnicaAire0,75 | D10: Barcelona | E10: Carnica | F10: 0.75 | G10: =IF(OR($E10="Secado",$E10="Bebidas"),60,120) -> 120 | H10: =IF(OR($E10="Secado",$E10="Bebidas"),15,60) -> 60 | I10: =IF(J10="AIRE","Aire",IF(J10="ETC","ETC",IF(J10="PLANO1","FPC1",IF(J10="PLANO2","FPC2",IF(J10="WESSUN","WeSSun"))))) -> Aire | J10: AIRE | K10: 8641.1782 | L10: 41.142001 | M10: 0.037088935 | N10: 21.459819
A11: 9 | B11: =_xlfn.CONCAT(D11,E11,J11,F11) -> BarcelonaFarmaceuticaAIRE0,3 | C11: =_xlfn.CONCAT(D11,E11,I11,F11) -> BarcelonaFarmaceuticaAire0,3 | D11: Barcelona | E11: Farmaceutica | F11: 0.3 | G11: =IF(OR($E11="Secado",$E11="Bebidas"),60,120) -> 120 | H11: =IF(OR($E11="Secado",$E11="Bebidas"),15,60) -> 60 | I11: =IF(J11="AIRE","Aire",IF(J11="ETC","ETC",IF(J11="PLANO1","FPC1",IF(J11="PLANO2","FPC2",IF(J11="WESSUN","WeSSun"))))) -> Aire | J11: AIRE | K11: 3456.4713 | L11: 33.646372 | M11: 0.0094103974 | N11: 13.61199
A12: 10 | B12: =_xlfn.CONCAT(D12,E12,J12,F12) -> BarcelonaFarmaceuticaAIRE0,45 | C12: =_xlfn.CONCAT(D12,E12,I12,F12) -> BarcelonaFarmaceuticaAire0,45 | D12: Barcelona | E12: Farmaceutica | F12: 0.45 | G12: =IF(OR($E12="Secado",$E12="Bebidas"),60,120) -> 120 | H12: =IF(OR($E12="Secado",$E12="Bebidas"),15,60) -> 60 | I12: =IF(J12="AIRE","Aire",IF(J12="ETC","ETC",IF(J12="PLANO1","FPC1",IF(J12="PLANO2","FPC2",IF(J12="WESSUN","WeSSun"))))) -> Aire | J12: AIRE | K12: 5184.7069 | L12: 36.417132 | M12: 0.017171417 | N12: 16.558787
A13: 11 | B13: =_xlfn.CONCAT(D13,E13,J13,F13) -> BarcelonaFarmaceuticaAIRE0,6 | C13: =_xlfn.CONCAT(D13,E13,I13,F13) -> BarcelonaFarmaceuticaAire0,6 | D13: Barcelona | E13: Farmaceutica | F13: 0.6 | G13: =IF(OR($E13="Secado",$E13="Bebidas"),60,120) -> 120 | H13: =IF(OR($E13="Secado",$E13="Bebidas"),15,60) -> 60 | I13: =IF(J13="AIRE","Aire",IF(J13="ETC","ETC",IF(J13="PLANO1","FPC1",IF(J13="PLANO2","FPC2",IF(J13="WESSUN","WeSSun"))))) -> Aire | J13: AIRE | K13: 6912.9425 | L13: 38.962002 | M13: 0.026694293 | N13: 19.306435
A14: 12 | B14: =_xlfn.CONCAT(D14,E14,J14,F14) -> BarcelonaFarmaceuticaAIRE0,75 | C14: =_xlfn.CONCAT(D14,E14,I14,F14) -> BarcelonaFarmaceuticaAire0,75 | D14: Barcelona | E14: Farmaceutica | F14: 0.75 | G14: =IF(OR($E14="Secado",$E14="Bebidas"),60,120) -> 120 | H14: =IF(OR($E14="Secado",$E14="Bebidas"),15,60) -> 60 | I14: =IF(J14="AIRE","Aire",IF(J14="ETC","ETC",IF(J14="PLANO1","FPC1",IF(J14="PLANO2","FPC2",IF(J14="WESSUN","WeSSun"))))) -> Aire | J14: AIRE | K14: 8641.1782 | L14: 41.142622 | M14: 0.0370947 | N14: 21.462757
... A502: 500 | B502: =_xlfn.CONCAT(D502,E502,J502,F502) -> ValenciaSecadoWESSUN0,75 | C502: =_xlfn.CONCAT(D502,E502,I502,F502) -> ValenciaSecadoWeSSun0,75 | D502: Valencia | E502: Secado | F502: 0.75 | G502: =IF(OR($E502="Secado",$E502="Bebidas"),60,120) -> 60 | H502: =IF(OR($E502="Secado",$E502="Bebidas"),15,60) -> 15 | I502: =IF(J502="AIRE","Aire",IF(J502="ETC","ETC",IF(J502="PLANO1","FPC1",IF(J502="PLANO2","FPC2",IF(J502="WESSUN","WeSSun"))))) -> WeSSun | J502: WESSUN | K502: 4195.2837 | L502: 905.62882 | M502: 0.73013146 | N502: 870.18128

Sheet CALCULOS
A2: TIR
A4: Incremento anual del coste de la Energía estimado | B4: VALOR ENERGIA PRODUCIDA | C4: Vida ÚTIL | D4: 0 | E4: 1 | F4: 2 | G4: 3 | H4: 4 | I4: 5 | J4: 6 | K4: 7 | L4: 8 | M4: 9 | N4: 10 | O4: 11 | P4: 12 | Q4: 13 | R4: 14 | S4: 15 | T4: 16 | U4: 17 | V4: 18 | W4: 19 | X4: 20 | Y4: 21 | Z4: 22 | AA4: 23 | AB4: 24 | AC4: 25 | AD4: 26 | AE4: 27 | AF4: 28 | AG4: 29 | AH4: 30
A5: =INTERFAZ!E61 -> 2 | B5: =INTERFAZ!E72/1000*INTERFAZ!E74*INTERFAZ!E53 -> 97946.33 | C5: =IF(INTERFAZ!E65>30,0,INTERFAZ!E65) -> 30 | D5: =-INTERFAZ!E80 -> -1060974 | E5: =IF(C5>=E4,B5,0) -> 97946.33 | F5: =IF($C$5>=F4,E5*(100+$A$5)%,0) -> 99905.256 | G5: =IF($C$5>=G4,F5*(100+$A$5)%,0) -> 101903.36 | H5: =IF($C$5>=H4,G5*(100+$A$5)%,0) -> 103941.43 | I5: =IF($C$5>=I4,H5*(100+$A$5)%,0) -> 106020.26 | J5: =IF($C$5>=J4,I5*(100+$A$5)%,0) -> 108140.66 | K5: =IF($C$5>=K4,J5*(100+$A$5)%,0) -> 110303.48 | L5: =IF($C$5>=L4,K5*(100+$A$5)%,0) -> 112509.55 | M5: =IF($C$5>=M4,L5*(100+$A$5)%,0) -> 114759.74 | ... AH5: =IF($C$5>=AH4,AG5*(100+$A$5)%,0) -> 173937.47
B8: TIR | C8: =IRR(D5:AH5) -> 0.10363797
A13: COSTE NIVELADO DE LA ENERGÍA
A15: Incremento anual del coste de la Energía estimado % | C15: VIDA UTIL | E15: 1 | F15: 2 | G15: 3 | H15: 4 | I15: 5 | J15: 6 | K15: 7 | L15: 8 | M15: 9 | N15: 10 | O15: 11 | P15: 12 | Q15: 13 | R15: 14 | S15: 15 | T15: 16 | U15: 17 | V15: 18 | W15: 19 | X15: 20 | Y15: 21 | Z15: 22 | AA15: 23 | AB15: 24 | AC15: 25 | AD15: 26 | AE15: 27 | AF15: 28 | AG15: 29 | AH15: 30
A16: =INTERFAZ!E61 -> 2 | C16: =IF(INTERFAZ!E65>30,0,INTERFAZ!E65) -> 30 | D16: COSTE DE ENERGÍA | E16: =IF(C16>=E15,(A18-A31)*A34,0) -> 86442.559 | F16: =IF($C$16>=F15,E16*(100+$A$16)%,0) -> 88171.41 | G16: =IF($C$16>=G15,F16*(100+$A$16)%,0) -> 89934.839 | H16: =IF($C$16>=H15,G16*(100+$A$16)%,0) -> 91733.535 | I16: =IF($C$16>=I15,H16*(100+$A$16)%,0) -> 93568.206 | J16: =IF($C$16>=J15,I16*(100+$A$16)%,0) -> 95439.57 | K16: =IF($C$16>=K15,J16*(100+$A$16)%,0) -> 97348.362 | L16: =IF($C$16>=L15,K16*(100+$A$16)%,0) -> 99295.329 | M16: =IF($C$16>=M15,L16*(100+$A$16)%,0) -> 101281.24 | ... AH16: =IF($C$16>=AH15,AG16*(100+$A$16)%,0) -> 153508.56
A17: Demanda anual de energía MWh/año | D17: PRECIO CO2 EVITADO | E17: =IF(C16>=E15,A37*A40,0) -> 12066.61 | F17: =IF($C$16>=F15,$E$17,0) -> 12066.61 | G17: =IF($C$16>=G15,$E$17,0) -> 12066.61 | H17: =IF($C$16>=H15,$E$17,0) -> 12066.61 | I17: =IF($C$16>=I15,$E$17,0) -> 12066.61 | J17: =IF($C$16>=J15,$E$17,0) -> 12066.61 | K17: =IF($C$16>=K15,$E$17,0) -> 12066.61 | L17: =IF($C$16>=L15,$E$17,0) -> 12066.61 | M17: =IF($C$16>=M15,$E$17,0) -> 12066.61 | ... AH17: =IF($C$16>=AH15,$E$17,0) -> 12066.61
A18: =INTERFAZ!E21 -> 5000 | D18: COSTES DE OPERACIÓN Y MANTENIMIENTO | E18: =IF(C16>=E15,A24,0) -> 53048.7 | F18: =IF($C$16>=F15,E18*(1+$A$26/100),0) -> 53579.187 | G18: =IF($C$16>=G15,F18*(1+$A$26/100),0) -> 54114.979 | H18: =IF($C$16>=H15,G18*(1+$A$26/100),0) -> 54656.129 | I18: =IF($C$16>=I15,H18*(1+$A$26/100),0) -> 55202.69 | J18: =IF($C$16>=J15,I18*(1+$A$26/100),0) -> 55754.717 | K18: =IF($C$16>=K15,J18*(1+$A$26/100),0) -> 56312.264 | L18: =IF($C$16>=L15,K18*(1+$A$26/100),0) -> 56875.387 | M18: =IF($C$16>=M15,L18*(1+$A$26/100),0) -> 57444.141 | ... AH18: =IF($C$16>=AH15,AG18*(1+$A$26/100),0) -> 70793.696
A21: GASTOS DE INVERSIÓN (Coste de inversión menos subvenciones) | D21: LCOE numerador | E21: =IF(C16>=E15,A22+E18+E16-E17,0) -> 1188398.6 | F21: =IF($C$16>=F20,F18+F16-F17,0) -> 129683.99 | G21: =IF($C$16>=G20,G18+G16-G17,0) -> 131983.21 | H21: =IF($C$16>=H20,H18+H16-H17,0) -> 134323.05 | I21: =IF($C$16>=I20,I18+I16-I17,0) -> 136704.29 | J21: =IF($C$16>=J20,J18+J16-J17,0) -> 139127.68 | K21: =IF($C$16>=K20,K18+K16-K17,0) -> 141594.02 | L21: =IF($C$16>=L20,L18+L16-L17,0) -> 144104.11 | M21: =IF($C$16>=M20,M18+M16-M17,0) -> 146658.77 | ... AH21: =IF($C$16>=AH20,AH18+AH16-AH17,0) -> 212235.65
A22: =INTERFAZ!E80 -> 1060974 | D22: LCOE denominador | E22: =IF($C$16>=E15,$A$18,0) -> 5000 | F22: =IF($C$16>=F15,$A$18,0) -> 5000 | G22: =IF($C$16>=G15,$A$18,0) -> 5000 | H22: =IF($C$16>=H15,$A$18,0) -> 5000 | I22: =IF($C$16>=I15,$A$18,0) -> 5000 | J22: =IF($C$16>=J15,$A$18,0) -> 5000 | K22: =IF($C$16>=K15,$A$18,0) -> 5000 | L22: =IF($C$16>=L15,$A$18,0) -> 5000 | ... AH22: =IF($C$16>=AH15,$A$18,0) -> 5000
A23: Coste de operación y mantenimiento Año1
A24: =INTERFAZ!E78*INTERFAZ!E59/100 -> 53048.7 | D24: LCOE | E24: =SUM(E21:AH21)/SUM(E22:AH22) -> 40.340517
A25: Inflación general. % Anual estimado
A26: =INTERFAZ!E63 -> 1
A30: CONTRIBUCIÓN ANUAL DE ENERGIA SOLAR TERMICA MWh/año
A31: =INTERFAZ!E72*INTERFAZ!E74/1000 -> 2655.9716
A33: COSTE ENERGÍA CONVENCIONAL €/MWh neto
A34: =INTERFAZ!E53 -> 36.877778
A36: CO2 ANUAL EVITADO tonCO2/año
A37: =A31*INTERFAZ!E55 -> 603.3305
A39: PRECIO CO2 EVITADO €/tonCO2 evitado
A40: =INTERFAZ!E57 -> 20
